<?xml version="1.0"?>
<robot name="mobile_robot" xmlns:xacro="http://www.ros.org/wiki/xacro">
  <xacro:property name="PI" value="3.141592653589793"/>
  <xacro:property name="wheel_radius" value="0.06"/>
  <xacro:property name="wheel_length" value="0.05"/>

  <xacro:macro name="box_inertial" params="mass x y z">
    <inertial>
      <mass value="${mass}"/>
      <origin xyz="0 0 0" rpy="0 0 0"/>
      <inertia
        ixx="${mass * (y*y + z*z) / 12.0}"
        ixy="0" ixz="0"
        iyy="${mass * (x*x + z*z) / 12.0}"
        iyz="0"
        izz="${mass * (x*x + y*y) / 12.0}"/>
    </inertial>
  </xacro:macro>

  <xacro:macro name="cylinder_inertial" params="mass radius length">
    <inertial>
      <mass value="${mass}"/>
      <origin xyz="0 0 0" rpy="0 0 0"/>
      <inertia
        ixx="${mass * (3 * radius * radius + length * length) / 12.0}"
        ixy="0" ixz="0"
        iyy="${mass * (3 * radius * radius + length * length) / 12.0}"
        iyz="0"
        izz="${mass * radius * radius / 2.0}"/>
    </inertial>
  </xacro:macro>

  <link name="base_footprint"/>

  <joint name="base_footprint_joint" type="fixed">
    <parent link="base_footprint"/>
    <child link="base_link"/>
    <origin xyz="0 0 0.06" rpy="0 0 0"/>
  </joint>

  <link name="base_link">
    <visual>
      <origin xyz="0 0 0.06" rpy="0 0 0"/>
      <geometry>
        <box size="0.46 0.34 0.12"/>
      </geometry>
      <material name="body_blue">
        <color rgba="0.10 0.28 0.55 1"/>
      </material>
    </visual>
    <collision>
      <origin xyz="0 0 0.06" rpy="0 0 0"/>
      <geometry>
        <box size="0.46 0.34 0.12"/>
      </geometry>
    </collision>
    <xacro:box_inertial mass="8.0" x="0.46" y="0.34" z="0.12"/>
  </link>

  <xacro:macro name="wheel" params="name x y">
    <link name="${name}">
      <visual>
        <origin xyz="0 0 0" rpy="${PI / 2} 0 0"/>
        <geometry>
          <cylinder radius="${wheel_radius}" length="${wheel_length}"/>
        </geometry>
        <material name="wheel_black">
          <color rgba="0.02 0.02 0.02 1"/>
        </material>
      </visual>
      <collision>
        <origin xyz="0 0 0" rpy="${PI / 2} 0 0"/>
        <geometry>
          <cylinder radius="${wheel_radius}" length="${wheel_length}"/>
        </geometry>
      </collision>
      <xacro:cylinder_inertial mass="0.2" radius="${wheel_radius}" length="${wheel_length}"/>
    </link>

    <joint name="${name}_joint" type="continuous">
      <parent link="base_link"/>
      <child link="${name}"/>
      <origin xyz="${x} ${y} 0.0" rpy="${-PI / 2} 0 0"/>
      <axis xyz="0 0 1"/>
    </joint>
  </xacro:macro>

  <xacro:wheel name="front_left_wheel" x="0.16" y="0.16"/>
  <xacro:wheel name="rear_left_wheel" x="-0.16" y="0.16"/>
  <xacro:wheel name="front_right_wheel" x="0.16" y="-0.16"/>
  <xacro:wheel name="rear_right_wheel" x="-0.16" y="-0.16"/>

  <link name="imu_link">
    <visual>
      <origin xyz="0 0 0" rpy="0 0 0"/>
      <geometry>
        <box size="0.05 0.05 0.03"/>
      </geometry>
      <material name="imu_green">
        <color rgba="0.05 0.65 0.25 1"/>
      </material>
    </visual>
    <collision>
      <geometry>
        <box size="0.05 0.05 0.03"/>
      </geometry>
    </collision>
    <xacro:box_inertial mass="0.02" x="0.05" y="0.05" z="0.03"/>
  </link>

  <joint name="imu_joint" type="fixed">
    <parent link="base_link"/>
    <child link="imu_link"/>
    <origin xyz="0.10 0 0.15" rpy="0 0 0"/>
  </joint>

  <gazebo reference="base_link">
    <material>Gazebo/Blue</material>
  </gazebo>
  <gazebo reference="front_left_wheel">
    <material>Gazebo/Black</material>
  </gazebo>
  <gazebo reference="rear_left_wheel">
    <material>Gazebo/Black</material>
  </gazebo>
  <gazebo reference="front_right_wheel">
    <material>Gazebo/Black</material>
  </gazebo>
  <gazebo reference="rear_right_wheel">
    <material>Gazebo/Black</material>
  </gazebo>

  <gazebo>
    <plugin name="planar_drive_controller" filename="libgazebo_ros_planar_move.so">
      <ros>
        <remapping>cmd_vel:=cmd_vel</remapping>
        <remapping>odom:=odom</remapping>
      </ros>
      <update_rate>100</update_rate>
      <publish_rate>100</publish_rate>
      <publish_odom>false</publish_odom>
      <publish_odom_tf>false</publish_odom_tf>
      <leftFrontJoint>front_left_wheel_joint</leftFrontJoint>
      <rightFrontJoint>front_right_wheel_joint</rightFrontJoint>
      <leftRearJoint>rear_left_wheel_joint</leftRearJoint>
      <rightRearJoint>rear_right_wheel_joint</rightRearJoint>
      <wheelSeparation>0.32</wheelSeparation>
      <wheelDiameter>0.12</wheelDiameter>
    </plugin>
  </gazebo>

  <gazebo reference="imu_link">
    <sensor name="imu_sensor" type="imu">
      <always_on>true</always_on>
      <update_rate>100</update_rate>
      <visualize>false</visualize>
      <plugin filename="libgazebo_ros_imu_sensor.so" name="imu_plugin">
        <ros>
          <remapping>~/out:=/livox/imu</remapping>
        </ros>
        <frameName>imu_link</frameName>
        <bodyName>imu_link</bodyName>
        <updateRateHZ>100.0</updateRateHZ>
        <gaussianNoise>0.0</gaussianNoise>
      </plugin>
    </sensor>
  </gazebo>

  <xacro:include filename="$(find ros2_livox_simulation)/urdf/mid360.xacro"/>
  <xacro:mid360 name="livox_frame" parent="base_link" topic="/livox/lidar">
    <origin xyz="0.12 0.0 0.20" rpy="0 0 0"/>
  </xacro:mid360>
</robot>
