<?xml version="1.0"?>
<robot name="mobile_robot" xmlns:xacro="http://www.ros.org/wiki/xacro">
  <xacro:arg name="enable_nav_rgbd_camera" default="false"/>
  <xacro:property name="PI" value="3.141592653589793"/>
  <!-- 底盘几何参数需要与 Nav2 footprint 保持同步，footprint 额外留安全余量。 -->
  <xacro:property name="chassis_length" value="0.46"/>
  <xacro:property name="chassis_width" value="0.34"/>
  <xacro:property name="chassis_height" value="0.12"/>
  <xacro:property name="chassis_mass" value="8.0"/>
  <xacro:property name="wheel_radius" value="0.06"/>
  <xacro:property name="wheel_length" value="0.05"/>
  <xacro:property name="wheel_x" value="0.16"/>
  <xacro:property name="wheel_y" value="0.16"/>
  <xacro:property name="imu_x" value="0.10"/>
  <xacro:property name="imu_z" value="0.15"/>
  <xacro:property name="livox_x" value="0.12"/>
  <xacro:property name="livox_z" value="0.20"/>
  <xacro:property name="nav_camera_x" value="0.24"/>
  <xacro:property name="nav_camera_z" value="0.20"/>

  <xacro:macro name="box_inertial" params="mass x y z">
    <inertial>
      <mass value="${mass}"/>
      <origin xyz="0 0 0" rpy="0 0 0"/>
      <inertia
        ixx="${mass * (y*y + z*z) / 12.0}"
        ixy="0" ixz="0"
        iyy="${mass * (x*x + z*z) / 12.0}"
        iyz="0"
        izz="${mass * (x*x + y*y) / 12.0}"/>
    </inertial>
  </xacro:macro>

  <xacro:macro name="cylinder_inertial" params="mass radius length">
    <inertial>
      <mass value="${mass}"/>
      <origin xyz="0 0 0" rpy="0 0 0"/>
      <inertia
        ixx="${mass * (3 * radius * radius + length * length) / 12.0}"
        ixy="0" ixz="0"
        iyy="${mass * (3 * radius * radius + length * length) / 12.0}"
        iyz="0"
        izz="${mass * radius * radius / 2.0}"/>
    </inertial>
  </xacro:macro>

  <link name="base_footprint"/>

  <joint name="base_footprint_joint" type="fixed">
    <parent link="base_footprint"/>
    <child link="base_link"/>
    <origin xyz="0 0 0.06" rpy="0 0 0"/>
  </joint>

  <link name="base_link">
    <visual>
      <origin xyz="0 0 0.06" rpy="0 0 0"/>
      <geometry>
        <box size="${chassis_length} ${chassis_width} ${chassis_height}"/>
      </geometry>
      <material name="body_blue">
        <color rgba="0.10 0.28 0.55 1"/>
      </material>
    </visual>
    <collision>
      <origin xyz="0 0 0.06" rpy="0 0 0"/>
      <geometry>
        <box size="${chassis_length} ${chassis_width} ${chassis_height}"/>
      </geometry>
    </collision>
    <xacro:box_inertial mass="${chassis_mass}" x="${chassis_length}" y="${chassis_width}" z="${chassis_height}"/>
  </link>

  <xacro:macro name="wheel" params="name x y">
    <link name="${name}">
      <visual>
        <origin xyz="0 0 0" rpy="${PI / 2} 0 0"/>
        <geometry>
          <cylinder radius="${wheel_radius}" length="${wheel_length}"/>
        </geometry>
        <material name="wheel_black">
          <color rgba="0.02 0.02 0.02 1"/>
        </material>
      </visual>
      <collision>
        <origin xyz="0 0 0" rpy="${PI / 2} 0 0"/>
        <geometry>
          <cylinder radius="${wheel_radius}" length="${wheel_length}"/>
        </geometry>
      </collision>
      <xacro:cylinder_inertial mass="0.2" radius="${wheel_radius}" length="${wheel_length}"/>
    </link>

    <joint name="${name}_joint" type="continuous">
      <parent link="base_link"/>
      <child link="${name}"/>
      <origin xyz="${x} ${y} 0.0" rpy="${-PI / 2} 0 0"/>
      <axis xyz="0 0 1"/>
    </joint>
  </xacro:macro>

  <xacro:wheel name="front_left_wheel" x="${wheel_x}" y="${wheel_y}"/>
  <xacro:wheel name="rear_left_wheel" x="${-wheel_x}" y="${wheel_y}"/>
  <xacro:wheel name="front_right_wheel" x="${wheel_x}" y="${-wheel_y}"/>
  <xacro:wheel name="rear_right_wheel" x="${-wheel_x}" y="${-wheel_y}"/>

  <link name="imu_link">
    <visual>
      <origin xyz="0 0 0" rpy="0 0 0"/>
      <geometry>
        <box size="0.05 0.05 0.03"/>
      </geometry>
      <material name="imu_green">
        <color rgba="0.05 0.65 0.25 1"/>
      </material>
    </visual>
    <collision>
      <geometry>
        <box size="0.05 0.05 0.03"/>
      </geometry>
    </collision>
    <xacro:box_inertial mass="0.02" x="0.05" y="0.05" z="0.03"/>
  </link>

  <joint name="imu_joint" type="fixed">
    <parent link="base_link"/>
    <child link="imu_link"/>
    <origin xyz="${imu_x} 0 ${imu_z}" rpy="0 0 0"/>
  </joint>

  <gazebo reference="base_link">
    <material>Gazebo/Blue</material>
  </gazebo>
  <gazebo reference="front_left_wheel">
    <material>Gazebo/Black</material>
  </gazebo>
  <gazebo reference="rear_left_wheel">
    <material>Gazebo/Black</material>
  </gazebo>
  <gazebo reference="front_right_wheel">
    <material>Gazebo/Black</material>
  </gazebo>
  <gazebo reference="rear_right_wheel">
    <material>Gazebo/Black</material>
  </gazebo>

  <gazebo>
    <plugin name="planar_drive_controller" filename="libgazebo_ros_planar_move.so">
      <ros>
        <remapping>cmd_vel:=cmd_vel</remapping>
        <remapping>odom:=odom</remapping>
      </ros>
      <update_rate>100</update_rate>
      <publish_rate>100</publish_rate>
      <publish_odom>false</publish_odom>
      <publish_odom_tf>false</publish_odom_tf>
      <leftFrontJoint>front_left_wheel_joint</leftFrontJoint>
      <rightFrontJoint>front_right_wheel_joint</rightFrontJoint>
      <leftRearJoint>rear_left_wheel_joint</leftRearJoint>
      <rightRearJoint>rear_right_wheel_joint</rightRearJoint>
      <wheelSeparation>${wheel_y * 2.0}</wheelSeparation>
      <wheelDiameter>${wheel_radius * 2.0}</wheelDiameter>
    </plugin>
  </gazebo>

  <gazebo reference="imu_link">
    <sensor name="imu_sensor" type="imu">
      <always_on>true</always_on>
      <update_rate>100</update_rate>
      <visualize>false</visualize>
      <plugin filename="libgazebo_ros_imu_sensor.so" name="imu_plugin">
        <ros>
          <remapping>~/out:=/livox/imu</remapping>
        </ros>
        <frameName>imu_link</frameName>
        <bodyName>imu_link</bodyName>
        <updateRateHZ>100.0</updateRateHZ>
        <gaussianNoise>0.0</gaussianNoise>
      </plugin>
    </sensor>
  </gazebo>

  <xacro:include filename="$(find ros2_livox_simulation)/urdf/mid360.xacro"/>
  <xacro:mid360 name="livox_frame" parent="base_link" topic="/livox/lidar">
    <origin xyz="${livox_x} 0.0 ${livox_z}" rpy="0 0 0"/>
  </xacro:mid360>

  <xacro:if value="$(arg enable_nav_rgbd_camera)">
    <link name="nav_camera_link">
      <visual>
        <origin xyz="0 0 0" rpy="0 0 0"/>
        <geometry>
          <box size="0.06 0.09 0.035"/>
        </geometry>
        <material name="nav_camera_black">
          <color rgba="0.01 0.01 0.01 1"/>
        </material>
      </visual>
      <collision>
        <origin xyz="0 0 0" rpy="0 0 0"/>
        <geometry>
          <box size="0.06 0.09 0.035"/>
        </geometry>
      </collision>
      <xacro:box_inertial mass="0.12" x="0.06" y="0.09" z="0.035"/>
    </link>

    <joint name="nav_camera_joint" type="fixed">
      <parent link="base_link"/>
      <child link="nav_camera_link"/>
      <origin xyz="${nav_camera_x} 0.0 ${nav_camera_z}" rpy="0 0 0"/>
    </joint>

    <link name="nav_camera_optical_frame"/>

    <joint name="nav_camera_optical_joint" type="fixed">
      <parent link="nav_camera_link"/>
      <child link="nav_camera_optical_frame"/>
      <!-- ROS 相机光学坐标系：x 向右，y 向下，z 向前。 -->
      <origin xyz="0 0 0" rpy="${-PI / 2} 0 ${-PI / 2}"/>
    </joint>

    <gazebo reference="nav_camera_link">
      <sensor name="nav_camera" type="depth">
        <always_on>true</always_on>
        <update_rate>30</update_rate>
        <visualize>false</visualize>
        <camera>
          <horizontal_fov>1.20</horizontal_fov>
          <image>
            <width>640</width>
            <height>480</height>
            <format>B8G8R8</format>
          </image>
          <depth_camera>
          </depth_camera>
          <clip>
            <near>0.10</near>
            <far>8.0</far>
          </clip>
          <noise>
            <type>gaussian</type>
            <mean>0.0</mean>
            <stddev>0.004</stddev>
          </noise>
        </camera>
        <plugin name="nav_camera_controller" filename="libgazebo_ros_camera.so">
          <ros>
            <namespace>nav_camera</namespace>
            <remapping>gemini_pro/image_raw:=color/image_raw</remapping>
            <remapping>gemini_pro/depth/image_raw:=depth/image_raw</remapping>
            <remapping>gemini_pro/camera_info:=color/camera_info</remapping>
            <remapping>gemini_pro/depth/camera_info:=depth/camera_info</remapping>
            <remapping>gemini_pro/points:=depth/points</remapping>
          </ros>
          <camera_name>gemini_pro</camera_name>
          <frame_name>nav_camera_optical_frame</frame_name>
          <min_depth>0.10</min_depth>
          <max_depth>8.0</max_depth>
        </plugin>
      </sensor>
    </gazebo>
  </xacro:if>
</robot>
